<sdf version='1.7'>
  <world name='ur5_cubes'>
    <gui fullscreen='0'>
      <camera name='user_camera'>
        <pose>1.86735 3.27434 2.57694 0 0.43 -1.99519</pose>
        <view_controller>orbit</view_controller>
        <projection_type>perspective</projection_type>
      </camera>
    </gui>
    <gravity>0 0 -9.81</gravity>
    <physics name='default_physics' default='0' type='ode'>
      <max_step_size>0.001</max_step_size>
      <real_time_factor>1</real_time_factor>
      <real_time_update_rate>1000</real_time_update_rate>
    </physics>
    <plugin name='ros_link_attacher_plugin' filename='libgazebo_ros_link_attacher.so'/>
    <scene>
      <ambient>0.4 0.4 0.4 1</ambient>
      <background>0.4 0.43 0.67 1</background>
      <shadows>1</shadows>
    </scene>
    <light name='sun' type='directional'>
      <cast_shadows>1</cast_shadows>
      <pose>0 0 10 0 -0 0</pose>
      <diffuse>0.8 0.8 0.8 1</diffuse>
      <specular>0.2 0.2 0.2 1</specular>
      <attenuation>
        <range>1000</range>
        <constant>0.9</constant>
        <linear>0.01</linear>
        <quadratic>0.001</quadratic>
      </attenuation>
      <direction>-0.5 0.1 -0.9</direction>
      <spot>
        <inner_angle>0</inner_angle>
        <outer_angle>0</outer_angle>
        <falloff>0</falloff>
      </spot>
    </light>
    <model name='ground_plane'>
      <static>1</static>
      <link name='link'>
        <collision name='collision'>
          <geometry>
            <plane>
              <normal>0 0 1</normal>
              <size>100 100</size>
            </plane>
          </geometry>
          <surface>
            <friction>
              <ode>
                <mu>100</mu>
                <mu2>50</mu2>
              </ode>
              <torsional>
                <ode/>
              </torsional>
            </friction>
            <contact>
              <ode/>
            </contact>
            <bounce/>
          </surface>
          <max_contacts>10</max_contacts>
        </collision>
        <visual name='visual'>
          <cast_shadows>0</cast_shadows>
          <geometry>
            <plane>
              <normal>0 0 1</normal>
              <size>100 100</size>
            </plane>
          </geometry>
          <material>
            <script>
              <uri>file://media/materials/scripts/gazebo.material</uri>
              <name>Gazebo/Grey</name>
            </script>
          </material>
        </visual>
        <self_collide>0</self_collide>
        <enable_wind>0</enable_wind>
        <kinematic>0</kinematic>
      </link>
      <pose>0 0 0 0 -0 0</pose>
    </model>
    <model name='ur_base'>
      <frame name='ur_base::__model__' attached_to='ur_base::top_plate'>
        <pose relative_to='__model__'>0 0 0 0 -0 0</pose>
      </frame>
      <static>1</static>
      <link name='ur_base::top_plate'>
        <pose relative_to='ur_base::__model__'>0 0 0.67501 0 -0 0</pose>
        <collision name='top_plate_collision'>
          <geometry>
            <box>
              <size>0.5 0.5 0.02</size>
            </box>
          </geometry>
          <surface>
            <contact>
              <collide_bitmask>1</collide_bitmask>
              <ode/>
            </contact>
            <bounce/>
            <friction>
              <torsional>
                <ode/>
              </torsional>
              <ode/>
            </friction>
          </surface>
          <max_contacts>10</max_contacts>
        </collision>
        <visual name='top_plate_visual'>
          <geometry>
            <box>
              <size>0.5 0.5 0.02</size>
            </box>
          </geometry>
          <material>
            <script>
              <uri>model://media/materials/scripts/gazebo.material</uri>
              <name>Gazebo/Grey</name>
            </script>
          </material>
        </visual>
        <self_collide>0</self_collide>
        <enable_wind>0</enable_wind>
        <kinematic>0</kinematic>
      </link>
      <link name='ur_base::leg1'>
        <pose relative_to='ur_base::__model__'>0.22 0.22 0.35 0 -0 0</pose>
        <visual name='leg1_visual'>
          <geometry>
            <box>
              <size>0.04 0.04 0.655</size>
            </box>
          </geometry>
          <material>
            <script>
              <uri>model://media/materials/scripts/gazebo.material</uri>
              <name>Gazebo/Grey</name>
            </script>
          </material>
        </visual>
        <self_collide>0</self_collide>
        <enable_wind>0</enable_wind>
        <kinematic>0</kinematic>
      </link>
      <link name='ur_base::leg2'>
        <pose relative_to='ur_base::__model__'>-0.22 0.22 0.35 0 -0 0</pose>
        <visual name='leg2_visual'>
          <geometry>
            <box>
              <size>0.04 0.04 0.655</size>
            </box>
          </geometry>
          <material>
            <script>
              <uri>model://media/materials/scripts/gazebo.material</uri>
              <name>Gazebo/Grey</name>
            </script>
          </material>
        </visual>
        <self_collide>0</self_collide>
        <enable_wind>0</enable_wind>
        <kinematic>0</kinematic>
      </link>
      <link name='ur_base::leg3'>
        <pose relative_to='ur_base::__model__'>0.22 -0.22 0.35 0 -0 0</pose>
        <visual name='leg3_visual'>
          <geometry>
            <box>
              <size>0.04 0.04 0.655</size>
            </box>
          </geometry>
          <material>
            <script>
              <uri>model://media/materials/scripts/gazebo.material</uri>
              <name>Gazebo/Grey</name>
            </script>
          </material>
        </visual>
        <self_collide>0</self_collide>
        <enable_wind>0</enable_wind>
        <kinematic>0</kinematic>
      </link>
      <link name='ur_base::leg4'>
        <pose relative_to='ur_base::__model__'>-0.22 -0.22 0.35 0 -0 0</pose>
        <visual name='leg4_visual'>
          <geometry>
            <box>
              <size>0.04 0.04 0.655</size>
            </box>
          </geometry>
          <material>
            <script>
              <uri>model://media/materials/scripts/gazebo.material</uri>
              <name>Gazebo/Grey</name>
            </script>
          </material>
        </visual>
        <self_collide>0</self_collide>
        <enable_wind>0</enable_wind>
        <kinematic>0</kinematic>
      </link>
    </model>
    <model name='cafe_table'>
      <link name='cafe_table::link'>
        <pose>0.75 0 0 0 -0 0</pose>
        <self_collide>0</self_collide>
        <kinematic>0</kinematic>
        <gravity>1</gravity>
        <inertial>
          <mass>1</mass>
          <pose>0 0 0 0 -0 0</pose>
          <inertia>
            <ixx>1</ixx>
            <ixy>0</ixy>
            <ixz>0</ixz>
            <iyy>1</iyy>
            <iyz>0</iyz>
            <izz>1</izz>
          </inertia>
        </inertial>
        <visual name='visual'>
          <geometry>
            <mesh>
              <uri>model://cafe_table/meshes/cafe_table.dae</uri>
              <scale>1 0.8 1</scale>
            </mesh>
          </geometry>
          <material>
            <shader type='pixel'>
              <normal_map>__default__</normal_map>
            </shader>
          </material>
          <pose>0 0 0 0 -0 0</pose>
          <cast_shadows>1</cast_shadows>
          <transparency>0</transparency>
        </visual>
        <collision name='surface'>
          <laser_retro>0</laser_retro>
          <max_contacts>10</max_contacts>
          <pose>0 0 0.755 0 -0 0</pose>
          <geometry>
            <box>
              <size>0.913 0.913 0.04</size>
            </box>
          </geometry>
          <surface>
            <friction>
              <ode>
                <mu>1</mu>
                <mu2>1</mu2>
                <fdir1>0 0 0</fdir1>
                <slip1>0</slip1>
                <slip2>0</slip2>
              </ode>
              <torsional>
                <coefficient>1</coefficient>
                <patch_radius>0</patch_radius>
                <surface_radius>0</surface_radius>
                <use_patch_radius>1</use_patch_radius>
                <ode>
                  <slip>0</slip>
                </ode>
              </torsional>
            </friction>
            <bounce>
              <restitution_coefficient>0</restitution_coefficient>
              <threshold>1e+06</threshold>
            </bounce>
            <contact>
              <collide_without_contact>0</collide_without_contact>
              <collide_without_contact_bitmask>1</collide_without_contact_bitmask>
              <collide_bitmask>1</collide_bitmask>
              <ode>
                <soft_cfm>0</soft_cfm>
                <soft_erp>0.2</soft_erp>
                <kp>1e+13</kp>
                <kd>1</kd>
                <max_vel>0.01</max_vel>
                <min_depth>0</min_depth>
              </ode>
              <bullet>
                <split_impulse>1</split_impulse>
                <split_impulse_penetration_threshold>-0.01</split_impulse_penetration_threshold>
                <soft_cfm>0</soft_cfm>
                <soft_erp>0.2</soft_erp>
                <kp>1e+13</kp>
                <kd>1</kd>
              </bullet>
            </contact>
          </surface>
        </collision>
        <collision name='column'>
          <laser_retro>0</laser_retro>
          <max_contacts>10</max_contacts>
          <pose>0 0 0.37 0 -0 0</pose>
          <geometry>
            <box>
              <size>0.042 0.042 0.74</size>
            </box>
          </geometry>
          <surface>
            <friction>
              <ode>
                <mu>1</mu>
                <mu2>1</mu2>
                <fdir1>0 0 0</fdir1>
                <slip1>0</slip1>
                <slip2>0</slip2>
              </ode>
              <torsional>
                <coefficient>1</coefficient>
                <patch_radius>0</patch_radius>
                <surface_radius>0</surface_radius>
                <use_patch_radius>1</use_patch_radius>
                <ode>
                  <slip>0</slip>
                </ode>
              </torsional>
            </friction>
            <bounce>
              <restitution_coefficient>0</restitution_coefficient>
              <threshold>1e+06</threshold>
            </bounce>
            <contact>
              <collide_without_contact>0</collide_without_contact>
              <collide_without_contact_bitmask>1</collide_without_contact_bitmask>
              <collide_bitmask>1</collide_bitmask>
              <ode>
                <soft_cfm>0</soft_cfm>
                <soft_erp>0.2</soft_erp>
                <kp>1e+13</kp>
                <kd>1</kd>
                <max_vel>0.01</max_vel>
                <min_depth>0</min_depth>
              </ode>
              <bullet>
                <split_impulse>1</split_impulse>
                <split_impulse_penetration_threshold>-0.01</split_impulse_penetration_threshold>
                <soft_cfm>0</soft_cfm>
                <soft_erp>0.2</soft_erp>
                <kp>1e+13</kp>
                <kd>1</kd>
              </bullet>
            </contact>
          </surface>
        </collision>
        <collision name='base'>
          <laser_retro>0</laser_retro>
          <max_contacts>10</max_contacts>
          <pose>0 0 0.02 0 -0 0</pose>
          <geometry>
            <box>
              <size>0.56 0.56 0.04</size>
            </box>
          </geometry>
          <surface>
            <friction>
              <ode>
                <mu>1</mu>
                <mu2>1</mu2>
                <fdir1>0 0 0</fdir1>
                <slip1>0</slip1>
                <slip2>0</slip2>
              </ode>
              <torsional>
                <coefficient>1</coefficient>
                <patch_radius>0</patch_radius>
                <surface_radius>0</surface_radius>
                <use_patch_radius>1</use_patch_radius>
                <ode>
                  <slip>0</slip>
                </ode>
              </torsional>
            </friction>
            <bounce>
              <restitution_coefficient>0</restitution_coefficient>
              <threshold>1e+06</threshold>
            </bounce>
            <contact>
              <collide_without_contact>0</collide_without_contact>
              <collide_without_contact_bitmask>1</collide_without_contact_bitmask>
              <collide_bitmask>1</collide_bitmask>
              <ode>
                <soft_cfm>0</soft_cfm>
                <soft_erp>0.2</soft_erp>
                <kp>1e+13</kp>
                <kd>1</kd>
                <max_vel>0.01</max_vel>
                <min_depth>0</min_depth>
              </ode>
              <bullet>
                <split_impulse>1</split_impulse>
                <split_impulse_penetration_threshold>-0.01</split_impulse_penetration_threshold>
                <soft_cfm>0</soft_cfm>
                <soft_erp>0.2</soft_erp>
                <kp>1e+13</kp>
                <kd>1</kd>
              </bullet>
            </contact>
          </surface>
        </collision>
        <enable_wind>0</enable_wind>
      </link>
      <static>1</static>
      <allow_auto_disable>1</allow_auto_disable>
      <pose>0 0 0 0 -0 0</pose>
    </model>
    <model name='cube1'>
      <pose>0.4 -0.2 0.775 0 -0 0</pose>
      <link name='link'>
        <pose>0 0 0.02 0 -0 0</pose>
        <inertial>
          <mass>0.0565</mass>
          <inertia>
            <ixx>2.35417e-05</ixx>
            <ixy>0</ixy>
            <ixz>0</ixz>
            <iyy>2.35417e-05</iyy>
            <iyz>0</iyz>
            <izz>2.35417e-05</izz>
          </inertia>
          <pose>0 0 0 0 -0 0</pose>
        </inertial>
        <collision name='collision'>
          <geometry>
            <box>
              <size>0.04 0.04 0.04</size>
            </box>
          </geometry>
          <surface>
            <contact>
              <poissons_ratio>0.347</poissons_ratio>
              <elastic_modulus>8.8e+09</elastic_modulus>
              <ode>
                <kp>100000</kp>
                <kd>1</kd>
                <max_vel>1</max_vel>
                <min_depth>0.001</min_depth>
              </ode>
            </contact>
            <friction>
              <torsional>
                <coefficient>1</coefficient>
                <use_patch_radius>0</use_patch_radius>
                <surface_radius>0.05</surface_radius>
                <ode/>
              </torsional>
              <ode/>
            </friction>
            <bounce/>
          </surface>
          <max_contacts>10</max_contacts>
        </collision>
        <visual name='visual'>
          <geometry>
            <box>
              <size>0.04 0.04 0.04</size>
            </box>
          </geometry>
        </visual>
        <self_collide>0</self_collide>
        <enable_wind>0</enable_wind>
        <kinematic>0</kinematic>
      </link>
    </model>
    <model name='cube2'>
      <pose>0.4 0 0.775 0 -0 0</pose>
      <link name='link'>
        <pose>0 0 0.02 0 -0 0</pose>
        <inertial>
          <mass>0.0565</mass>
          <inertia>
            <ixx>2.35417e-05</ixx>
            <ixy>0</ixy>
            <ixz>0</ixz>
            <iyy>2.35417e-05</iyy>
            <iyz>0</iyz>
            <izz>2.35417e-05</izz>
          </inertia>
          <pose>0 0 0 0 -0 0</pose>
        </inertial>
        <collision name='collision'>
          <geometry>
            <box>
              <size>0.04 0.04 0.04</size>
            </box>
          </geometry>
          <surface>
            <contact>
              <poissons_ratio>0.347</poissons_ratio>
              <elastic_modulus>8.8e+09</elastic_modulus>
              <ode>
                <kp>100000</kp>
                <kd>1</kd>
                <max_vel>1</max_vel>
                <min_depth>0.001</min_depth>
              </ode>
            </contact>
            <friction>
              <torsional>
                <coefficient>1</coefficient>
                <use_patch_radius>0</use_patch_radius>
                <surface_radius>0.05</surface_radius>
                <ode/>
              </torsional>
              <ode/>
            </friction>
            <bounce/>
          </surface>
          <max_contacts>10</max_contacts>
        </collision>
        <visual name='visual'>
          <geometry>
            <box>
              <size>0.04 0.04 0.04</size>
            </box>
          </geometry>
        </visual>
        <self_collide>0</self_collide>
        <enable_wind>0</enable_wind>
        <kinematic>0</kinematic>
      </link>
    </model>
    <model name='cube3'>
      <pose>0.4 0.2 0.775 0 -0 0</pose>
      <link name='link'>
        <pose>0 0 0.02 0 -0 0</pose>
        <inertial>
          <mass>0.0565</mass>
          <inertia>
            <ixx>2.35417e-05</ixx>
            <ixy>0</ixy>
            <ixz>0</ixz>
            <iyy>2.35417e-05</iyy>
            <iyz>0</iyz>
            <izz>2.35417e-05</izz>
          </inertia>
          <pose>0 0 0 0 -0 0</pose>
        </inertial>
        <collision name='collision'>
          <geometry>
            <box>
              <size>0.04 0.04 0.04</size>
            </box>
          </geometry>
          <surface>
            <contact>
              <poissons_ratio>0.347</poissons_ratio>
              <elastic_modulus>8.8e+09</elastic_modulus>
              <ode>
                <kp>100000</kp>
                <kd>1</kd>
                <max_vel>1</max_vel>
                <min_depth>0.001</min_depth>
              </ode>
            </contact>
            <friction>
              <torsional>
                <coefficient>1</coefficient>
                <use_patch_radius>0</use_patch_radius>
                <surface_radius>0.05</surface_radius>
                <ode/>
              </torsional>
              <ode/>
            </friction>
            <bounce/>
          </surface>
          <max_contacts>10</max_contacts>
        </collision>
        <visual name='visual'>
          <geometry>
            <box>
              <size>0.04 0.04 0.04</size>
            </box>
          </geometry>
        </visual>
        <self_collide>0</self_collide>
        <enable_wind>0</enable_wind>
        <kinematic>0</kinematic>
      </link>
    </model>
    <magnetic_field>6e-06 2.3e-05 -4.2e-05</magnetic_field>
    <atmosphere type='adiabatic'/>
    <wind/>
    <spherical_coordinates>
      <surface_model>EARTH_WGS84</surface_model>
      <latitude_deg>0</latitude_deg>
      <longitude_deg>0</longitude_deg>
      <elevation>0</elevation>
      <heading_deg>0</heading_deg>
    </spherical_coordinates>
    <model name='robot'>
      <joint name='world_joint' type='fixed'>
        <pose relative_to='__model__'>0 0 0 0 -0 0</pose>
        <parent>world</parent>
        <child>base_link</child>
      </joint>
      <link name='base_link'>
        <pose relative_to='world_joint'>0 0 0 0 -0 0</pose>
        <inertial>
          <pose>0 0 0 0 -0 0</pose>
          <mass>4</mass>
          <inertia>
            <ixx>0.00443333</ixx>
            <ixy>0</ixy>
            <ixz>0</ixz>
            <iyy>0.00443333</iyy>
            <iyz>0</iyz>
            <izz>0.0072</izz>
          </inertia>
        </inertial>
        <collision name='base_link_inertia_collision'>
          <pose>0 0 0 0 -0 0</pose>
          <geometry>
            <mesh>
              <scale>1 1 1</scale>
              <uri>/home/yfu/yolo_ws/src/universal_robot/ur_description/meshes/ur5/collision/base.stl</uri>
            </mesh>
          </geometry>
          <max_contacts>10</max_contacts>
          <surface>
            <contact>
              <ode/>
            </contact>
            <bounce/>
            <friction>
              <torsional>
                <ode/>
              </torsional>
              <ode/>
            </friction>
          </surface>
        </collision>
        <visual name='base_link_inertia_visual'>
          <pose>0 0 0 0 -0 0</pose>
          <geometry>
            <mesh>
              <scale>1 1 1</scale>
              <uri>/home/yfu/yolo_ws/src/universal_robot/ur_description/meshes/ur5/visual/base.dae</uri>
            </mesh>
          </geometry>
        </visual>
        <self_collide>0</self_collide>
        <enable_wind>0</enable_wind>
        <kinematic>0</kinematic>
      </link>
      <joint name='shoulder_pan_joint' type='revolute'>
        <pose relative_to='base_link'>0 0 0.089159 0 -0 3.14159</pose>
        <parent>base_link</parent>
        <child>shoulder_link</child>
        <axis>
          <xyz>0 0 1</xyz>
          <limit>
            <lower>-6.28319</lower>
            <upper>6.28319</upper>
            <effort>150</effort>
            <velocity>3.14159</velocity>
          </limit>
          <dynamics>
            <damping>0</damping>
            <friction>0</friction>
            <spring_reference>0</spring_reference>
            <spring_stiffness>0</spring_stiffness>
          </dynamics>
        </axis>
      </joint>
      <link name='shoulder_link'>
        <pose relative_to='shoulder_pan_joint'>0 0 0 0 -0 0</pose>
        <inertial>
          <pose>0 -0.00193 -0.02561 0 -0 0</pose>
          <mass>3.7</mass>
          <inertia>
            <ixx>0.0149724</ixx>
            <ixy>0</ixy>
            <ixz>0</ixz>
            <iyy>0.0149724</iyy>
            <iyz>0</iyz>
            <izz>0.0104063</izz>
          </inertia>
        </inertial>
        <collision name='shoulder_link_collision'>
          <pose>0 0 0 0 -0 3.14159</pose>
          <geometry>
            <mesh>
              <scale>1 1 1</scale>
              <uri>/home/yfu/yolo_ws/src/universal_robot/ur_description/meshes/ur5/collision/shoulder.stl</uri>
            </mesh>
          </geometry>
          <surface>
            <contact>
              <ode/>
            </contact>
            <friction>
              <ode/>
              <torsional>
                <ode/>
              </torsional>
            </friction>
            <bounce/>
          </surface>
          <max_contacts>10</max_contacts>
        </collision>
        <visual name='shoulder_link_visual'>
          <pose>0 0 0 0 -0 3.14159</pose>
          <geometry>
            <mesh>
              <scale>1 1 1</scale>
              <uri>/home/yfu/yolo_ws/src/universal_robot/ur_description/meshes/ur5/visual/shoulder.dae</uri>
            </mesh>
          </geometry>
        </visual>
        <self_collide>1</self_collide>
        <enable_wind>0</enable_wind>
        <kinematic>0</kinematic>
      </link>
      <joint name='shoulder_lift_joint' type='revolute'>
        <pose relative_to='shoulder_link'>0 0 0 1.5708 -0 0</pose>
        <parent>shoulder_link</parent>
        <child>upper_arm_link</child>
        <axis>
          <xyz>0 0 1</xyz>
          <limit>
            <lower>-6.28319</lower>
            <upper>6.28319</upper>
            <effort>150</effort>
            <velocity>3.14159</velocity>
          </limit>
          <dynamics>
            <damping>0</damping>
            <friction>0</friction>
            <spring_reference>0</spring_reference>
            <spring_stiffness>0</spring_stiffness>
          </dynamics>
        </axis>
      </joint>
      <link name='upper_arm_link'>
        <pose relative_to='shoulder_lift_joint'>0 0 0 0 -0 0</pose>
        <inertial>
          <pose>-0.2125 0 0.11336 3.14159 1.57079 3.14159</pose>
          <mass>8.393</mass>
          <inertia>
            <ixx>0.133886</ixx>
            <ixy>0</ixy>
            <ixz>0</ixz>
            <iyy>0.133886</iyy>
            <iyz>0</iyz>
            <izz>0.0151074</izz>
          </inertia>
        </inertial>
        <collision name='upper_arm_link_collision'>
          <pose>0 0 0.13585 1.5708 0 -1.5708</pose>
          <geometry>
            <mesh>
              <scale>1 1 1</scale>
              <uri>/home/yfu/yolo_ws/src/universal_robot/ur_description/meshes/ur5/collision/upperarm.stl</uri>
            </mesh>
          </geometry>
          <surface>
            <contact>
              <ode/>
            </contact>
            <friction>
              <ode/>
              <torsional>
                <ode/>
              </torsional>
            </friction>
            <bounce/>
          </surface>
          <max_contacts>10</max_contacts>
        </collision>
        <visual name='upper_arm_link_visual'>
          <pose>0 0 0.13585 1.5708 0 -1.5708</pose>
          <geometry>
            <mesh>
              <scale>1 1 1</scale>
              <uri>/home/yfu/yolo_ws/src/universal_robot/ur_description/meshes/ur5/visual/upperarm.dae</uri>
            </mesh>
          </geometry>
        </visual>
        <self_collide>1</self_collide>
        <enable_wind>0</enable_wind>
        <kinematic>0</kinematic>
      </link>
      <joint name='elbow_joint' type='revolute'>
        <pose relative_to='upper_arm_link'>-0.425 0 0 0 -0 0</pose>
        <parent>upper_arm_link</parent>
        <child>forearm_link</child>
        <axis>
          <xyz>0 0 1</xyz>
          <limit>
            <lower>-3.14159</lower>
            <upper>3.14159</upper>
            <effort>150</effort>
            <velocity>3.14159</velocity>
          </limit>
          <dynamics>
            <damping>0</damping>
            <friction>0</friction>
            <spring_reference>0</spring_reference>
            <spring_stiffness>0</spring_stiffness>
          </dynamics>
        </axis>
      </joint>
      <link name='forearm_link'>
        <pose relative_to='elbow_joint'>0 0 0 0 -0 0</pose>
        <inertial>
          <pose>-0.24225 0 0.0265 3.14159 1.57079 3.14159</pose>
          <mass>2.33</mass>
          <inertia>
            <ixx>0.0312168</ixx>
            <ixy>0</ixy>
            <ixz>0</ixz>
            <iyy>0.0312168</iyy>
            <iyz>0</iyz>
            <izz>0.004095</izz>
          </inertia>
        </inertial>
        <collision name='forearm_link_collision'>
          <pose>0 0 0.0165 1.5708 0 -1.5708</pose>
          <geometry>
            <mesh>
              <scale>1 1 1</scale>
              <uri>/home/yfu/yolo_ws/src/universal_robot/ur_description/meshes/ur5/collision/forearm.stl</uri>
            </mesh>
          </geometry>
          <surface>
            <contact>
              <ode/>
            </contact>
            <friction>
              <ode/>
              <torsional>
                <ode/>
              </torsional>
            </friction>
            <bounce/>
          </surface>
          <max_contacts>10</max_contacts>
        </collision>
        <visual name='forearm_link_visual'>
          <pose>0 0 0.0165 1.5708 0 -1.5708</pose>
          <geometry>
            <mesh>
              <scale>1 1 1</scale>
              <uri>/home/yfu/yolo_ws/src/universal_robot/ur_description/meshes/ur5/visual/forearm.dae</uri>
            </mesh>
          </geometry>
        </visual>
        <self_collide>1</self_collide>
        <enable_wind>0</enable_wind>
        <kinematic>0</kinematic>
      </link>
      <joint name='wrist_1_joint' type='revolute'>
        <pose relative_to='forearm_link'>-0.39225 0 0.10915 0 -0 0</pose>
        <parent>forearm_link</parent>
        <child>wrist_1_link</child>
        <axis>
          <xyz>0 0 1</xyz>
          <limit>
            <lower>-6.28319</lower>
            <upper>6.28319</upper>
            <effort>28</effort>
            <velocity>3.14159</velocity>
          </limit>
          <dynamics>
            <damping>0</damping>
            <friction>0</friction>
            <spring_reference>0</spring_reference>
            <spring_stiffness>0</spring_stiffness>
          </dynamics>
        </axis>
      </joint>
      <link name='wrist_1_link'>
        <pose relative_to='wrist_1_joint'>0 0 0 0 -0 0</pose>
        <inertial>
          <pose>0 -0.01634 -0.0018 0 -0 0</pose>
          <mass>1.219</mass>
          <inertia>
            <ixx>0.00201389</ixx>
            <ixy>0</ixy>
            <ixz>0</ixz>
            <iyy>0.00201389</iyy>
            <iyz>0</iyz>
            <izz>0.0021942</izz>
          </inertia>
        </inertial>
        <collision name='wrist_1_link_collision'>
          <pose>0 0 -0.093 1.5708 -0 0</pose>
          <geometry>
            <mesh>
              <scale>1 1 1</scale>
              <uri>/home/yfu/yolo_ws/src/universal_robot/ur_description/meshes/ur5/collision/wrist1.stl</uri>
            </mesh>
          </geometry>
          <surface>
            <contact>
              <ode/>
            </contact>
            <friction>
              <ode/>
              <torsional>
                <ode/>
              </torsional>
            </friction>
            <bounce/>
          </surface>
          <max_contacts>10</max_contacts>
        </collision>
        <visual name='wrist_1_link_visual'>
          <pose>0 0 -0.093 1.5708 -0 0</pose>
          <geometry>
            <mesh>
              <scale>1 1 1</scale>
              <uri>/home/yfu/yolo_ws/src/universal_robot/ur_description/meshes/ur5/visual/wrist1.dae</uri>
            </mesh>
          </geometry>
        </visual>
        <self_collide>1</self_collide>
        <enable_wind>0</enable_wind>
        <kinematic>0</kinematic>
      </link>
      <joint name='wrist_2_joint' type='revolute'>
        <pose relative_to='wrist_1_link'>0 -0.09465 -0 1.5708 -0 0</pose>
        <parent>wrist_1_link</parent>
        <child>wrist_2_link</child>
        <axis>
          <xyz>0 0 1</xyz>
          <limit>
            <lower>-6.28319</lower>
            <upper>6.28319</upper>
            <effort>28</effort>
            <velocity>3.14159</velocity>
          </limit>
          <dynamics>
            <damping>0</damping>
            <friction>0</friction>
            <spring_reference>0</spring_reference>
            <spring_stiffness>0</spring_stiffness>
          </dynamics>
        </axis>
      </joint>
      <link name='wrist_2_link'>
        <pose relative_to='wrist_2_joint'>0 0 0 0 -0 0</pose>
        <inertial>
          <pose>0 0.01634 -0.0018 0 -0 0</pose>
          <mass>1.219</mass>
          <inertia>
            <ixx>0.00183104</ixx>
            <ixy>0</ixy>
            <ixz>0</ixz>
            <iyy>0.00183104</iyy>
            <iyz>0</iyz>
            <izz>0.0021942</izz>
          </inertia>
        </inertial>
        <collision name='wrist_2_link_collision'>
          <pose>0 0 -0.095 0 -0 0</pose>
          <geometry>
            <mesh>
              <scale>1 1 1</scale>
              <uri>/home/yfu/yolo_ws/src/universal_robot/ur_description/meshes/ur5/collision/wrist2.stl</uri>
            </mesh>
          </geometry>
          <surface>
            <contact>
              <ode/>
            </contact>
            <friction>
              <ode/>
              <torsional>
                <ode/>
              </torsional>
            </friction>
            <bounce/>
          </surface>
          <max_contacts>10</max_contacts>
        </collision>
        <visual name='wrist_2_link_visual'>
          <pose>0 0 -0.095 0 -0 0</pose>
          <geometry>
            <mesh>
              <scale>1 1 1</scale>
              <uri>/home/yfu/yolo_ws/src/universal_robot/ur_description/meshes/ur5/visual/wrist2.dae</uri>
            </mesh>
          </geometry>
        </visual>
        <self_collide>1</self_collide>
        <enable_wind>0</enable_wind>
        <kinematic>0</kinematic>
      </link>
      <joint name='wrist_3_joint' type='revolute'>
        <pose relative_to='wrist_2_link'>0 0.0823 -0 -1.5708 0 0</pose>
        <parent>wrist_2_link</parent>
        <child>wrist_3_link</child>
        <axis>
          <xyz>0 0 1</xyz>
          <limit>
            <lower>-6.28319</lower>
            <upper>6.28319</upper>
            <effort>28</effort>
            <velocity>3.14159</velocity>
          </limit>
          <dynamics>
            <damping>0</damping>
            <friction>0</friction>
            <spring_reference>0</spring_reference>
            <spring_stiffness>0</spring_stiffness>
          </dynamics>
        </axis>
      </joint>
      <link name='wrist_3_link'>
        <pose relative_to='wrist_3_joint'>0 0 0 0 -0 0</pose>
        <inertial>
          <pose>0 -3e-06 0.016665 0 -0 0</pose>
          <mass>0.41442</mass>
          <inertia>
            <ixx>0.000389886</ixx>
            <ixy>-4.24379e-10</ixy>
            <ixz>-5.79551e-10</ixz>
            <iyy>0.000368156</iyy>
            <iyz>-1.88008e-08</iyz>
            <izz>0.000266897</izz>
          </inertia>
        </inertial>
        <collision name='wrist_3_link_collision'>
          <pose>0 0 -0.0818 1.5708 -0 0</pose>
          <geometry>
            <mesh>
              <scale>1 1 1</scale>
              <uri>/home/yfu/yolo_ws/src/universal_robot/ur_description/meshes/ur5/collision/wrist3.stl</uri>
            </mesh>
          </geometry>
          <surface>
            <contact>
              <ode/>
            </contact>
            <friction>
              <ode/>
              <torsional>
                <ode/>
              </torsional>
            </friction>
            <bounce/>
          </surface>
          <max_contacts>10</max_contacts>
        </collision>
        <collision name='wrist_3_link_fixed_joint_lump__robotiq_arg2f_base_link_collision_1'>
          <pose>0 0 0 0 -0 0</pose>
          <geometry>
            <mesh>
              <scale>1 1 1</scale>
              <uri>/home/yfu/yolo_ws/src/robotiq/robotiq_2f_85_gripper_visualization/meshes/collision/robotiq_arg2f_base_link.stl</uri>
            </mesh>
          </geometry>
          <surface>
            <contact>
              <ode/>
            </contact>
            <friction>
              <ode/>
              <torsional>
                <ode/>
              </torsional>
            </friction>
            <bounce/>
          </surface>
          <max_contacts>10</max_contacts>
        </collision>
        <visual name='wrist_3_link_visual'>
          <pose>0 0 -0.0818 1.5708 -0 0</pose>
          <geometry>
            <mesh>
              <scale>1 1 1</scale>
              <uri>/home/yfu/yolo_ws/src/universal_robot/ur_description/meshes/ur5/visual/wrist3.dae</uri>
            </mesh>
          </geometry>
        </visual>
        <visual name='wrist_3_link_fixed_joint_lump__robotiq_arg2f_base_link_visual_1'>
          <pose>0 0 0 0 -0 0</pose>
          <geometry>
            <mesh>
              <scale>1 1 1</scale>
              <uri>/home/yfu/yolo_ws/src/robotiq/robotiq_2f_85_gripper_visualization/meshes/visual/robotiq_arg2f_base_link.stl</uri>
            </mesh>
          </geometry>
          <material>
            <script>
              <name>Gazebo/Black</name>
              <uri>file://media/materials/scripts/gazebo.material</uri>
            </script>
          </material>
        </visual>
        <self_collide>1</self_collide>
        <enable_wind>0</enable_wind>
        <kinematic>0</kinematic>
      </link>
      <joint name='finger_joint' type='revolute'>
        <pose relative_to='wrist_3_link'>0 -0.030601 0.054904 0 -0 3.14159</pose>
        <parent>wrist_3_link</parent>
        <child>left_outer_knuckle</child>
        <axis>
          <xyz>1 0 0</xyz>
          <limit>
            <lower>0</lower>
            <upper>0.8</upper>
            <effort>1000</effort>
            <velocity>0.5</velocity>
          </limit>
          <dynamics>
            <spring_reference>0</spring_reference>
            <spring_stiffness>0</spring_stiffness>
          </dynamics>
        </axis>
      </joint>
      <link name='left_outer_knuckle'>
        <pose relative_to='finger_joint'>0 0 0 0 -0 0</pose>
        <inertial>
          <pose>0.000164 0.055483 -0.010075 0 -0 0</pose>
          <mass>0.0311462</mass>
          <inertia>
            <ixx>5.1136e-05</ixx>
            <ixy>-1.50984e-07</ixy>
            <ixz>1.67498e-07</ixz>
            <iyy>2.6195e-05</iyy>
            <iyz>2.19801e-05</iyz>
            <izz>2.77118e-05</izz>
          </inertia>
        </inertial>
        <collision name='left_outer_knuckle_collision'>
          <pose>0 0 0 0 -0 0</pose>
          <geometry>
            <mesh>
              <scale>0.001 0.001 0.001</scale>
              <uri>/home/yfu/yolo_ws/src/robotiq/robotiq_2f_85_gripper_visualization/meshes/collision/robotiq_arg2f_85_outer_knuckle.dae</uri>
            </mesh>
          </geometry>
          <surface>
            <contact>
              <ode/>
            </contact>
            <friction>
              <ode/>
              <torsional>
                <ode/>
              </torsional>
            </friction>
            <bounce/>
          </surface>
          <max_contacts>10</max_contacts>
        </collision>
        <collision name='left_outer_knuckle_fixed_joint_lump__left_outer_finger_collision_1'>
          <pose>0 0.0315 -0.0041 0 -0 0</pose>
          <geometry>
            <mesh>
              <scale>0.001 0.001 0.001</scale>
              <uri>/home/yfu/yolo_ws/src/robotiq/robotiq_2f_85_gripper_visualization/meshes/collision/robotiq_arg2f_85_outer_finger.dae</uri>
            </mesh>
          </geometry>
          <surface>
            <contact>
              <ode/>
            </contact>
            <friction>
              <ode/>
              <torsional>
                <ode/>
              </torsional>
            </friction>
            <bounce/>
          </surface>
          <max_contacts>10</max_contacts>
        </collision>
        <visual name='left_outer_knuckle_visual'>
          <pose>0 0 0 0 -0 0</pose>
          <geometry>
            <mesh>
              <scale>0.001 0.001 0.001</scale>
              <uri>/home/yfu/yolo_ws/src/robotiq/robotiq_2f_85_gripper_visualization/meshes/visual/robotiq_arg2f_85_outer_knuckle.dae</uri>
            </mesh>
          </geometry>
          <material>
            <script>
              <name>Gazebo/Grey</name>
              <uri>file://media/materials/scripts/gazebo.material</uri>
            </script>
          </material>
        </visual>
        <visual name='left_outer_knuckle_fixed_joint_lump__left_outer_finger_visual_1'>
          <pose>0 0.0315 -0.0041 0 -0 0</pose>
          <geometry>
            <mesh>
              <scale>0.001 0.001 0.001</scale>
              <uri>/home/yfu/yolo_ws/src/robotiq/robotiq_2f_85_gripper_visualization/meshes/visual/robotiq_arg2f_85_outer_finger.dae</uri>
            </mesh>
          </geometry>
          <material>
            <script>
              <name>Gazebo/Black</name>
              <uri>file://media/materials/scripts/gazebo.material</uri>
            </script>
          </material>
        </visual>
        <self_collide>0</self_collide>
        <enable_wind>0</enable_wind>
        <kinematic>0</kinematic>
      </link>
      <joint name='left_inner_finger_joint' type='revolute'>
        <pose relative_to='left_outer_knuckle'>0 0.0376 0.043 0 -0 0</pose>
        <parent>left_outer_knuckle</parent>
        <child>left_inner_finger</child>
        <axis>
          <xyz>1 0 0</xyz>
          <limit>
            <lower>-0.8757</lower>
            <upper>0</upper>
            <effort>1000</effort>
            <velocity>0.5</velocity>
          </limit>
          <dynamics>
            <spring_reference>0</spring_reference>
            <spring_stiffness>0</spring_stiffness>
          </dynamics>
        </axis>
      </joint>
      <link name='left_inner_finger'>
        <pose relative_to='left_inner_finger_joint'>0 0 0 0 -0 0</pose>
        <inertial>
          <pose>0.0003 0.016008 -0.013695 0 -0 0</pose>
          <mass>0.0104003</mass>
          <inertia>
            <ixx>2.71909e-06</ixx>
            <ixy>1.35402e-21</ixy>
            <ixz>-7.18173e-22</ixz>
            <iyy>7.691e-07</iyy>
            <iyz>6.74715e-07</iyz>
            <izz>2.30315e-06</izz>
          </inertia>
        </inertial>
        <collision name='left_inner_finger_collision'>
          <pose>0 0 0 0 -0 0</pose>
          <geometry>
            <mesh>
              <scale>0.001 0.001 0.001</scale>
              <uri>/home/yfu/yolo_ws/src/robotiq/robotiq_2f_85_gripper_visualization/meshes/collision/robotiq_arg2f_85_inner_finger.dae</uri>
            </mesh>
          </geometry>
          <surface>
            <contact>
              <ode/>
            </contact>
            <friction>
              <ode/>
              <torsional>
                <ode/>
              </torsional>
            </friction>
            <bounce/>
          </surface>
          <max_contacts>10</max_contacts>
        </collision>
        <collision name='left_inner_finger_pad_collision_1'>
          <pose>0 -0.02202 0.03242 0 -0 0</pose>
          <geometry>
            <box>
              <size>0.022 0.00635 0.0375</size>
            </box>
          </geometry>
          <surface>
            <contact>
              <ode/>
            </contact>
            <friction>
              <ode/>
              <torsional>
                <ode/>
              </torsional>
            </friction>
            <bounce/>
          </surface>
          <max_contacts>10</max_contacts>
        </collision>
        <visual name='left_inner_finger_visual'>
          <pose>0 0 0 0 -0 0</pose>
          <geometry>
            <mesh>
              <scale>0.001 0.001 0.001</scale>
              <uri>/home/yfu/yolo_ws/src/robotiq/robotiq_2f_85_gripper_visualization/meshes/visual/robotiq_arg2f_85_inner_finger.dae</uri>
            </mesh>
          </geometry>
          <material>
            <script>
              <name>Gazebo/Grey</name>
              <uri>file://media/materials/scripts/gazebo.material</uri>
            </script>
          </material>
        </visual>
        <visual name='left_inner_finger_pad_visual_1'>
          <pose>0 -0.02202 0.03242 0 -0 0</pose>
          <geometry>
            <box>
              <size>0.022 0.00635 0.0375</size>
            </box>
          </geometry>
          <material>
            <script>
              <name>Gazebo/Grey</name>
              <uri>file://media/materials/scripts/gazebo.material</uri>
            </script>
          </material>
        </visual>
        <self_collide>0</self_collide>
        <enable_wind>0</enable_wind>
        <kinematic>0</kinematic>
      </link>
      <joint name='left_inner_knuckle_joint' type='revolute'>
        <pose relative_to='wrist_3_link'>0 -0.0127 0.06142 0 -0 3.14159</pose>
        <parent>wrist_3_link</parent>
        <child>left_inner_knuckle</child>
        <axis>
          <xyz>1 0 0</xyz>
          <limit>
            <lower>0</lower>
            <upper>0.8757</upper>
            <effort>1000</effort>
            <velocity>0.5</velocity>
          </limit>
          <dynamics>
            <spring_reference>0</spring_reference>
            <spring_stiffness>0</spring_stiffness>
          </dynamics>
        </axis>
      </joint>
      <link name='left_inner_knuckle'>
        <pose relative_to='left_inner_knuckle_joint'>0 0 0 0 -0 0</pose>
        <inertial>
          <pose>0.000123 0.050785 0.00104 0 -0 0</pose>
          <mass>0.0271177</mass>
          <inertia>
            <ixx>2.6191e-05</ixx>
            <ixy>-2.43617e-07</ixy>
            <ixz>-6.3779e-09</ixz>
            <iyy>2.82702e-06</iyy>
            <iyz>-5.37201e-07</iyz>
            <izz>2.83696e-05</izz>
          </inertia>
        </inertial>
        <collision name='left_inner_knuckle_collision'>
          <pose>0 0 0 0 -0 0</pose>
          <geometry>
            <mesh>
              <scale>0.001 0.001 0.001</scale>
              <uri>/home/yfu/yolo_ws/src/robotiq/robotiq_2f_85_gripper_visualization/meshes/collision/robotiq_arg2f_85_inner_knuckle.dae</uri>
            </mesh>
          </geometry>
          <surface>
            <contact>
              <ode/>
            </contact>
            <friction>
              <ode/>
              <torsional>
                <ode/>
              </torsional>
            </friction>
            <bounce/>
          </surface>
          <max_contacts>10</max_contacts>
        </collision>
        <visual name='left_inner_knuckle_visual'>
          <pose>0 0 0 0 -0 0</pose>
          <geometry>
            <mesh>
              <scale>0.001 0.001 0.001</scale>
              <uri>/home/yfu/yolo_ws/src/robotiq/robotiq_2f_85_gripper_visualization/meshes/visual/robotiq_arg2f_85_inner_knuckle.dae</uri>
            </mesh>
          </geometry>
          <material>
            <script>
              <name>Gazebo/Black</name>
              <uri>file://media/materials/scripts/gazebo.material</uri>
            </script>
          </material>
        </visual>
        <self_collide>0</self_collide>
        <enable_wind>0</enable_wind>
        <kinematic>0</kinematic>
      </link>
      <joint name='right_finger_joint' type='revolute'>
        <pose relative_to='wrist_3_link'>-0 0.030601 0.054904 0 -0 0</pose>
        <parent>wrist_3_link</parent>
        <child>right_outer_knuckle</child>
        <axis>
          <xyz>1 0 0</xyz>
          <limit>
            <lower>0</lower>
            <upper>0.81</upper>
            <effort>1000</effort>
            <velocity>0.5</velocity>
          </limit>
          <dynamics>
            <spring_reference>0</spring_reference>
            <spring_stiffness>0</spring_stiffness>
          </dynamics>
        </axis>
      </joint>
      <link name='right_outer_knuckle'>
        <pose relative_to='right_finger_joint'>0 0 0 0 -0 0</pose>
        <inertial>
          <pose>0.000164 0.055483 -0.010075 0 -0 0</pose>
          <mass>0.0311462</mass>
          <inertia>
            <ixx>5.1136e-05</ixx>
            <ixy>-1.50984e-07</ixy>
            <ixz>1.67498e-07</ixz>
            <iyy>2.6195e-05</iyy>
            <iyz>2.19801e-05</iyz>
            <izz>2.77118e-05</izz>
          </inertia>
        </inertial>
        <collision name='right_outer_knuckle_collision'>
          <pose>0 0 0 0 -0 0</pose>
          <geometry>
            <mesh>
              <scale>0.001 0.001 0.001</scale>
              <uri>/home/yfu/yolo_ws/src/robotiq/robotiq_2f_85_gripper_visualization/meshes/collision/robotiq_arg2f_85_outer_knuckle.dae</uri>
            </mesh>
          </geometry>
          <surface>
            <contact>
              <ode/>
            </contact>
            <friction>
              <ode/>
              <torsional>
                <ode/>
              </torsional>
            </friction>
            <bounce/>
          </surface>
          <max_contacts>10</max_contacts>
        </collision>
        <collision name='right_outer_knuckle_fixed_joint_lump__right_outer_finger_collision_1'>
          <pose>0 0.0315 -0.0041 0 -0 0</pose>
          <geometry>
            <mesh>
              <scale>0.001 0.001 0.001</scale>
              <uri>/home/yfu/yolo_ws/src/robotiq/robotiq_2f_85_gripper_visualization/meshes/collision/robotiq_arg2f_85_outer_finger.dae</uri>
            </mesh>
          </geometry>
          <surface>
            <contact>
              <ode/>
            </contact>
            <friction>
              <ode/>
              <torsional>
                <ode/>
              </torsional>
            </friction>
            <bounce/>
          </surface>
          <max_contacts>10</max_contacts>
        </collision>
        <visual name='right_outer_knuckle_visual'>
          <pose>0 0 0 0 -0 0</pose>
          <geometry>
            <mesh>
              <scale>0.001 0.001 0.001</scale>
              <uri>/home/yfu/yolo_ws/src/robotiq/robotiq_2f_85_gripper_visualization/meshes/visual/robotiq_arg2f_85_outer_knuckle.dae</uri>
            </mesh>
          </geometry>
          <material>
            <script>
              <name>Gazebo/Grey</name>
              <uri>file://media/materials/scripts/gazebo.material</uri>
            </script>
          </material>
        </visual>
        <visual name='right_outer_knuckle_fixed_joint_lump__right_outer_finger_visual_1'>
          <pose>0 0.0315 -0.0041 0 -0 0</pose>
          <geometry>
            <mesh>
              <scale>0.001 0.001 0.001</scale>
              <uri>/home/yfu/yolo_ws/src/robotiq/robotiq_2f_85_gripper_visualization/meshes/visual/robotiq_arg2f_85_outer_finger.dae</uri>
            </mesh>
          </geometry>
          <material>
            <script>
              <name>Gazebo/Black</name>
              <uri>file://media/materials/scripts/gazebo.material</uri>
            </script>
          </material>
        </visual>
        <self_collide>0</self_collide>
        <enable_wind>0</enable_wind>
        <kinematic>0</kinematic>
      </link>
      <joint name='right_inner_finger_joint' type='revolute'>
        <pose relative_to='right_outer_knuckle'>0 0.0376 0.043 0 -0 0</pose>
        <parent>right_outer_knuckle</parent>
        <child>right_inner_finger</child>
        <axis>
          <xyz>1 0 0</xyz>
          <limit>
            <lower>-0.8757</lower>
            <upper>0</upper>
            <effort>1000</effort>
            <velocity>0.5</velocity>
          </limit>
          <dynamics>
            <spring_reference>0</spring_reference>
            <spring_stiffness>0</spring_stiffness>
          </dynamics>
        </axis>
      </joint>
      <link name='right_inner_finger'>
        <pose relative_to='right_inner_finger_joint'>0 0 0 0 -0 0</pose>
        <inertial>
          <pose>0.0003 0.016008 -0.013695 0 -0 0</pose>
          <mass>0.0104003</mass>
          <inertia>
            <ixx>2.71909e-06</ixx>
            <ixy>1.35402e-21</ixy>
            <ixz>-7.18173e-22</ixz>
            <iyy>7.691e-07</iyy>
            <iyz>6.74715e-07</iyz>
            <izz>2.30315e-06</izz>
          </inertia>
        </inertial>
        <collision name='right_inner_finger_collision'>
          <pose>0 0 0 0 -0 0</pose>
          <geometry>
            <mesh>
              <scale>0.001 0.001 0.001</scale>
              <uri>/home/yfu/yolo_ws/src/robotiq/robotiq_2f_85_gripper_visualization/meshes/collision/robotiq_arg2f_85_inner_finger.dae</uri>
            </mesh>
          </geometry>
          <surface>
            <contact>
              <ode/>
            </contact>
            <friction>
              <ode/>
              <torsional>
                <ode/>
              </torsional>
            </friction>
            <bounce/>
          </surface>
          <max_contacts>10</max_contacts>
        </collision>
        <collision name='right_inner_finger_pad_collision_1'>
          <pose>0 -0.02202 0.03242 0 -0 0</pose>
          <geometry>
            <box>
              <size>0.022 0.00635 0.0375</size>
            </box>
          </geometry>
          <surface>
            <contact>
              <ode/>
            </contact>
            <friction>
              <ode/>
              <torsional>
                <ode/>
              </torsional>
            </friction>
            <bounce/>
          </surface>
          <max_contacts>10</max_contacts>
        </collision>
        <visual name='right_inner_finger_visual'>
          <pose>0 0 0 0 -0 0</pose>
          <geometry>
            <mesh>
              <scale>0.001 0.001 0.001</scale>
              <uri>/home/yfu/yolo_ws/src/robotiq/robotiq_2f_85_gripper_visualization/meshes/visual/robotiq_arg2f_85_inner_finger.dae</uri>
            </mesh>
          </geometry>
          <material>
            <script>
              <name>Gazebo/Grey</name>
              <uri>file://media/materials/scripts/gazebo.material</uri>
            </script>
          </material>
        </visual>
        <visual name='right_inner_finger_pad_visual_1'>
          <pose>0 -0.02202 0.03242 0 -0 0</pose>
          <geometry>
            <box>
              <size>0.022 0.00635 0.0375</size>
            </box>
          </geometry>
          <material>
            <script>
              <name>Gazebo/Grey</name>
              <uri>file://media/materials/scripts/gazebo.material</uri>
            </script>
          </material>
        </visual>
        <self_collide>0</self_collide>
        <enable_wind>0</enable_wind>
        <kinematic>0</kinematic>
      </link>
      <joint name='right_inner_knuckle_joint' type='revolute'>
        <pose relative_to='wrist_3_link'>-0 0.0127 0.06142 0 -0 0</pose>
        <parent>wrist_3_link</parent>
        <child>right_inner_knuckle</child>
        <axis>
          <xyz>1 0 0</xyz>
          <limit>
            <lower>0</lower>
            <upper>0.8757</upper>
            <effort>1000</effort>
            <velocity>0.5</velocity>
          </limit>
          <dynamics>
            <spring_reference>0</spring_reference>
            <spring_stiffness>0</spring_stiffness>
          </dynamics>
        </axis>
      </joint>
      <link name='right_inner_knuckle'>
        <pose relative_to='right_inner_knuckle_joint'>0 0 0 0 -0 0</pose>
        <inertial>
          <pose>0.000123 0.050785 0.00104 0 -0 0</pose>
          <mass>0.0271177</mass>
          <inertia>
            <ixx>2.6191e-05</ixx>
            <ixy>-2.43617e-07</ixy>
            <ixz>-6.3779e-09</ixz>
            <iyy>2.82702e-06</iyy>
            <iyz>-5.37201e-07</iyz>
            <izz>2.83696e-05</izz>
          </inertia>
        </inertial>
        <collision name='right_inner_knuckle_collision'>
          <pose>0 0 0 0 -0 0</pose>
          <geometry>
            <mesh>
              <scale>0.001 0.001 0.001</scale>
              <uri>/home/yfu/yolo_ws/src/robotiq/robotiq_2f_85_gripper_visualization/meshes/collision/robotiq_arg2f_85_inner_knuckle.dae</uri>
            </mesh>
          </geometry>
          <surface>
            <contact>
              <ode/>
            </contact>
            <friction>
              <ode/>
              <torsional>
                <ode/>
              </torsional>
            </friction>
            <bounce/>
          </surface>
          <max_contacts>10</max_contacts>
        </collision>
        <visual name='right_inner_knuckle_visual'>
          <pose>0 0 0 0 -0 0</pose>
          <geometry>
            <mesh>
              <scale>0.001 0.001 0.001</scale>
              <uri>/home/yfu/yolo_ws/src/robotiq/robotiq_2f_85_gripper_visualization/meshes/visual/robotiq_arg2f_85_inner_knuckle.dae</uri>
            </mesh>
          </geometry>
          <material>
            <script>
              <name>Gazebo/Black</name>
              <uri>file://media/materials/scripts/gazebo.material</uri>
            </script>
          </material>
        </visual>
        <self_collide>0</self_collide>
        <enable_wind>0</enable_wind>
        <kinematic>0</kinematic>
      </link>
      <plugin name='ros_control' filename='libgazebo_ros_control.so'>
        <robotNamespace>/</robotNamespace>
      </plugin>
      <plugin name='mimic_robotiq_85_1' filename='libroboticsgroup_upatras_gazebo_mimic_joint_plugin.so'>
        <joint>finger_joint</joint>
        <mimicJoint>left_inner_knuckle_joint</mimicJoint>
        <multiplier>1.0</multiplier>
        <robotNamespace>/</robotNamespace>
      </plugin>
      <plugin name='mimic_robotiq_85_2' filename='libroboticsgroup_upatras_gazebo_mimic_joint_plugin.so'>
        <joint>finger_joint</joint>
        <mimicJoint>left_inner_finger_joint</mimicJoint>
        <multiplier>-1.0</multiplier>
        <robotNamespace>/</robotNamespace>
      </plugin>
      <plugin name='mimic_robotiq_85_3' filename='libroboticsgroup_upatras_gazebo_mimic_joint_plugin.so'>
        <joint>finger_joint</joint>
        <mimicJoint>right_inner_knuckle_joint</mimicJoint>
        <multiplier>1.0</multiplier>
        <robotNamespace>/</robotNamespace>
      </plugin>
      <plugin name='mimic_robotiq_85_4' filename='libroboticsgroup_upatras_gazebo_mimic_joint_plugin.so'>
        <joint>finger_joint</joint>
        <mimicJoint>right_inner_finger_joint</mimicJoint>
        <multiplier>-1.0</multiplier>
        <robotNamespace>/</robotNamespace>
      </plugin>
      <plugin name='mimic_robotiq_85_5' filename='libroboticsgroup_upatras_gazebo_mimic_joint_plugin.so'>
        <joint>finger_joint</joint>
        <mimicJoint>right_finger_joint</mimicJoint>
        <multiplier>1.0</multiplier>
        <robotNamespace>/</robotNamespace>
      </plugin>
      <frame name='base_link-base_fixed_joint' attached_to='base_link'>
        <pose>0 0 0 0 -0 3.14159</pose>
      </frame>
      <frame name='base' attached_to='base_link-base_fixed_joint'/>
      <frame name='base_link-base_link_inertia' attached_to='base_link'>
        <pose>0 0 0 0 -0 3.14159</pose>
      </frame>
      <frame name='base_link_inertia' attached_to='base_link-base_link_inertia'/>
      <frame name='ur_robotiq_joint' attached_to='tool0'>
        <pose>0 0 0 0 -0 0</pose>
      </frame>
      <frame name='robotiq_arg2f_base_link' attached_to='ur_robotiq_joint'/>
      <frame name='left_outer_finger_joint' attached_to='left_outer_knuckle'>
        <pose>0 0.0315 -0.0041 0 -0 0</pose>
      </frame>
      <frame name='left_outer_finger' attached_to='left_outer_finger_joint'/>
      <frame name='left_inner_finger_pad_joint' attached_to='left_inner_finger'>
        <pose>0 -0.02202 0.03242 0 -0 0</pose>
      </frame>
      <frame name='left_inner_finger_pad' attached_to='left_inner_finger_pad_joint'/>
      <frame name='right_outer_finger_joint' attached_to='right_outer_knuckle'>
        <pose>0 0.0315 -0.0041 0 -0 0</pose>
      </frame>
      <frame name='right_outer_finger' attached_to='right_outer_finger_joint'/>
      <frame name='right_inner_finger_pad_joint' attached_to='right_inner_finger'>
        <pose>0 -0.02202 0.03242 0 -0 0</pose>
      </frame>
      <frame name='right_inner_finger_pad' attached_to='right_inner_finger_pad_joint'/>
      <frame name='flange-tool0' attached_to='flange'>
        <pose>0 0 0 1.5708 -0 1.5708</pose>
      </frame>
      <frame name='tool0' attached_to='flange-tool0'/>
      <frame name='wrist_3-flange' attached_to='wrist_3_link'>
        <pose>0 0 0 1.57079 -1.57079 3.14159</pose>
      </frame>
      <frame name='flange' attached_to='wrist_3-flange'/>
      <pose>0.11 0 0.69 0 0 -1.5707</pose>
    </model>
    <model name='kinect'>
      <pose>0.570216 -1.31305 0.036 0 -0 0</pose>
      <link name='link'>
        <inertial>
          <mass>0.1</mass>
          <pose>0 0 0 0 -0 0</pose>
          <inertia>
            <ixx>1</ixx>
            <ixy>0</ixy>
            <ixz>0</ixz>
            <iyy>1</iyy>
            <iyz>0</iyz>
            <izz>1</izz>
          </inertia>
        </inertial>
        <collision name='collision'>
          <geometry>
            <box>
              <size>0.073 0.276 0.072</size>
            </box>
          </geometry>
          <max_contacts>10</max_contacts>
          <surface>
            <contact>
              <ode/>
            </contact>
            <bounce/>
            <friction>
              <torsional>
                <ode/>
              </torsional>
              <ode/>
            </friction>
          </surface>
        </collision>
        <visual name='visual'>
          <geometry>
            <mesh>
              <uri>model://kinect/meshes/kinect.dae</uri>
            </mesh>
          </geometry>
        </visual>
        <sensor name='camera' type='depth'>
          <update_rate>20</update_rate>
          <camera>
            <horizontal_fov>1.0472</horizontal_fov>
            <image>
              <width>640</width>
              <height>480</height>
              <format>R8G8B8</format>
            </image>
            <clip>
              <near>0.05</near>
              <far>3</far>
            </clip>
          </camera>
          <plugin name='camera_plugin' filename='libgazebo_ros_openni_kinect.so'>
            <baseline>0.2</baseline>
            <alwaysOn>1</alwaysOn>
            <updateRate>0.0</updateRate>
            <cameraName>camera_ir</cameraName>
            <imageTopicName>/camera/color/image_raw</imageTopicName>
            <cameraInfoTopicName>/camera/color/camera_info</cameraInfoTopicName>
            <depthImageTopicName>/camera/depth/image_raw</depthImageTopicName>
            <depthImageCameraInfoTopicName>/camera/depth/camera_info</depthImageCameraInfoTopicName>
            <pointCloudTopicName>/camera/depth/points</pointCloudTopicName>
            <frameName>world</frameName>
            <pointCloudCutoff>0.5</pointCloudCutoff>
            <pointCloudCutoffMax>3.0</pointCloudCutoffMax>
            <distortionK1>0</distortionK1>
            <distortionK2>0</distortionK2>
            <distortionK3>0</distortionK3>
            <distortionT1>0</distortionT1>
            <distortionT2>0</distortionT2>
            <CxPrime>0</CxPrime>
            <Cx>0</Cx>
            <Cy>0</Cy>
            <focalLength>0</focalLength>
            <hackBaseline>0</hackBaseline>
          </plugin>
        </sensor>
        <self_collide>0</self_collide>
        <enable_wind>0</enable_wind>
        <kinematic>0</kinematic>
      </link>
    </model>
    <state world_name='ur5_cubes'>
      <sim_time>264 166000000</sim_time>
      <real_time>454 895115733</real_time>
      <wall_time>1743302498 556347059</wall_time>
      <iterations>264166</iterations>
      <model name='cafe_table'>
        <pose>0.009513 0.030537 0 0 -0 0</pose>
        <scale>1 1 1</scale>
        <link name='cafe_table::link'>
          <pose>0.759513 0.030537 0 0 -0 0</pose>
          <velocity>0 0 0 0 -0 0</velocity>
          <acceleration>0 0 0 0 -0 0</acceleration>
          <wrench>0 0 0 0 -0 0</wrench>
        </link>
      </model>
      <model name='cube1'>
        <pose>0.4 -0.2 0.773999 0 -0 0</pose>
        <scale>1 1 1</scale>
        <link name='link'>
          <pose>0.4 -0.2 0.793999 0 -0 0</pose>
          <velocity>0 0 0 0 -0 0</velocity>
          <acceleration>0 0 -0 0 -0 0</acceleration>
          <wrench>0 0 -0 0 -0 0</wrench>
        </link>
      </model>
      <model name='cube2'>
        <pose>0.4 0 0.773999 0 -0 0</pose>
        <scale>1 1 1</scale>
        <link name='link'>
          <pose>0.4 -0 0.793999 0 -0 0</pose>
          <velocity>0 0 0 0 -0 0</velocity>
          <acceleration>-0 0 -0 0 -0 0</acceleration>
          <wrench>-0 0 -0 0 -0 0</wrench>
        </link>
      </model>
      <model name='cube3'>
        <pose>0.4 0.2 0.773999 0 -0 0</pose>
        <scale>1 1 1</scale>
        <link name='link'>
          <pose>0.4 0.2 0.793999 0 -0 0</pose>
          <velocity>0 0 0 0 -0 0</velocity>
          <acceleration>-0 0 -0 0 -0 0</acceleration>
          <wrench>-0 0 -0 0 -0 0</wrench>
        </link>
      </model>
      <model name='ground_plane'>
        <pose>0 0 0 0 -0 0</pose>
        <scale>1 1 1</scale>
        <link name='link'>
          <pose>0 0 0 0 -0 0</pose>
          <velocity>0 0 0 0 -0 0</velocity>
          <acceleration>0 0 0 0 -0 0</acceleration>
          <wrench>0 0 0 0 -0 0</wrench>
        </link>
      </model>
      <model name='kinect'>
        <pose>1.11512 0.00023 0.811003 1e-06 -9e-05 3.14001</pose>
        <scale>1 1 1</scale>
        <link name='link'>
          <pose>1.11512 0.00023 0.811003 1e-06 -9e-05 3.14001</pose>
          <velocity>0.000187 -6e-06 0.000168 0.000164 0.005181 0</velocity>
          <acceleration>-0.001293 -0.004861 -0.019947 0.135028 -0.03594 0</acceleration>
          <wrench>-0.000129 -0.000486 -0.001995 0 -0 0</wrench>
        </link>
      </model>
      <model name='robot'>
        <pose>0.11 -0 0.69 0 1.6e-05 -1.5707</pose>
        <scale>1 1 1</scale>
        <link name='base_link'>
          <pose>0.11 -0 0.69 0 1.6e-05 -1.5707</pose>
          <velocity>1e-06 -0 -2e-06 -0.000881 9e-05 0</velocity>
          <acceleration>-0.002313 0.008139 0.005426 0.145414 -0.252894 -1e-06</acceleration>
          <wrench>-0.009253 0.032556 0.021704 0 -0 0</wrench>
        </link>
        <link name='forearm_link'>
          <pose>0.111099 2.2e-05 1.20416 1.57085 0.299586 3.14091</pose>
          <velocity>0.000225 -0.001044 2.7e-05 0.002826 0.000742 0.003036</velocity>
          <acceleration>-0.275916 -0.467642 -0.094803 1.24768 0.18517 -2.71619</acceleration>
          <wrench>-0.642884 -1.08961 -0.22089 0 -0 0</wrench>
        </link>
        <link name='left_inner_finger'>
          <pose>0.694342 0.108908 1.19514 2.84526 -0.000796 1.57039</pose>
          <velocity>-0.003995 0.000368 -0.006317 0.011703 0.133835 0.008575</velocity>
          <acceleration>-1.31376 -0.203129 -6.50336 0.153263 1.26924 2.78013</acceleration>
          <wrench>-0.013663 -0.002113 -0.067637 0 -0 0</wrench>
        </link>
        <link name='left_inner_knuckle'>
          <pose>0.630607 0.108924 1.21383 2.84509 -0.000646 1.57032</pose>
          <velocity>0.000203 0.000222 0.000362 -0.005548 0.011263 0.000711</velocity>
          <acceleration>0.274754 -0.661873 0.08722 2.6329 1.41049 -2.91992</acceleration>
          <wrench>0.007451 -0.017948 0.002365 0 -0 0</wrench>
        </link>
        <link name='left_outer_knuckle'>
          <pose>0.645824 0.108903 1.22529 2.84525 -0.000813 1.5704</pose>
          <velocity>0.000179 -0.000474 0.0004 0.013472 0.138441 0.009274</velocity>
          <acceleration>3.14825 1.54826 -5.41041 0.41833 -1.28399 -0.511833</acceleration>
          <wrench>0.098056 0.048222 -0.168514 0 -0 0</wrench>
        </link>
        <link name='right_inner_finger'>
          <pose>0.563891 0.108999 1.1553 -2.84518 0.000784 -1.57128</pose>
          <velocity>0.001456 0.000426 -0.000276 0.010424 -0.021515 -0.000325</velocity>
          <acceleration>1.07285 -0.428398 -0.614904 0.856031 -1.10747 -0.733212</acceleration>
          <wrench>0.011158 -0.004455 -0.006395 0 -0 0</wrench>
        </link>
        <link name='right_inner_knuckle'>
          <pose>0.606315 0.108939 1.2064 -2.84513 0.000695 -1.57127</pose>
          <velocity>0.000219 3.7e-05 0.000322 -2e-06 -0.003553 0.000956</velocity>
          <acceleration>0.295636 0.597436 0.015763 0.087092 0.36753 -2.09726</acceleration>
          <wrench>0.008017 0.016201 0.000427 0 -0 0</wrench>
        </link>
        <link name='right_outer_knuckle'>
          <pose>0.587292 0.108946 1.20741 -2.84518 0.000787 -1.57129</pose>
          <velocity>0.000216 -0.000204 0.00028 0.010838 -0.023793 -0.001272</velocity>
          <acceleration>0.350455 0.568735 -0.899077 1.28123 -0.038036 -2.74965</acceleration>
          <wrench>0.010915 0.017714 -0.028003 0 -0 0</wrench>
        </link>
        <link name='shoulder_link'>
          <pose>0.11 -0 0.779159 3.8e-05 0 3.14089</pose>
          <velocity>-1.5e-05 0.00012 5e-06 0.00175 -0.000282 0.003059</velocity>
          <acceleration>0.014919 -0.234108 -0.007509 0.576991 0.751426 -1.35517</acceleration>
          <wrench>0.055201 -0.866199 -0.027782 0 -0 0</wrench>
        </link>
        <link name='upper_arm_link'>
          <pose>0.11 0 0.779159 1.59162 1.56821 -3.12147</pose>
          <velocity>-1.2e-05 0.000104 2.6e-05 0.00262 0.000527 0.00307</velocity>
          <acceleration>0.023648 -0.278895 -0.033426 -0.028214 -0.736491 0.576632</acceleration>
          <wrench>0.198479 -2.34077 -0.280544 0 -0 0</wrench>
        </link>
        <link name='wrist_1_link'>
          <pose>0.485954 0.108916 1.31991 -1.57098 1.27433 -0.000877</pose>
          <velocity>-1.7e-05 -0.00024 6.4e-05 0.002933 -0.002096 0.003075</velocity>
          <acceleration>-0.190992 -0.62542 -0.118521 2.34112 -1.5292 1.83044</acceleration>
          <wrench>-0.23282 -0.762387 -0.144477 0 -0 0</wrench>
        </link>
        <link name='wrist_2_link'>
          <pose>0.576474 0.108855 1.34757 -1.27433 0.000701 -1.57127</pose>
          <velocity>-7.2e-05 -4.8e-05 0.000255 7.5e-05 -0.002083 0.002139</velocity>
          <acceleration>-0.222655 -0.565247 0.151417 -2.55572 0.417326 -1.90061</acceleration>
          <wrench>-0.271417 -0.689036 0.184577 0 -0 0</wrench>
        </link>
        <link name='wrist_3_link'>
          <pose>0.600518 0.108898 1.26886 -2.84513 0.000701 -1.57127</pose>
          <velocity>9.1e-05 1.2e-05 0.000305 0.00043 -0.002065 0.000846</velocity>
          <acceleration>0.055794 0.011283 0.243321 -0.412921 1.55866 1.37184</acceleration>
          <wrench>0.023122 0.004676 0.100837 0 -0 0</wrench>
        </link>
      </model>
      <model name='ur_base'>
        <pose>0 0 0 0 -0 0</pose>
        <scale>1 1 1</scale>
        <link name='ur_base::leg1'>
          <pose>0.22 0.22 0.35 0 -0 0</pose>
          <velocity>0 0 0 0 -0 0</velocity>
          <acceleration>0 0 0 0 -0 0</acceleration>
          <wrench>0 0 0 0 -0 0</wrench>
        </link>
        <link name='ur_base::leg2'>
          <pose>-0.22 0.22 0.35 0 -0 0</pose>
          <velocity>0 0 0 0 -0 0</velocity>
          <acceleration>0 0 0 0 -0 0</acceleration>
          <wrench>0 0 0 0 -0 0</wrench>
        </link>
        <link name='ur_base::leg3'>
          <pose>0.22 -0.22 0.35 0 -0 0</pose>
          <velocity>0 0 0 0 -0 0</velocity>
          <acceleration>0 0 0 0 -0 0</acceleration>
          <wrench>0 0 0 0 -0 0</wrench>
        </link>
        <link name='ur_base::leg4'>
          <pose>-0.22 -0.22 0.35 0 -0 0</pose>
          <velocity>0 0 0 0 -0 0</velocity>
          <acceleration>0 0 0 0 -0 0</acceleration>
          <wrench>0 0 0 0 -0 0</wrench>
        </link>
        <link name='ur_base::top_plate'>
          <pose>0 0 0.67501 0 -0 0</pose>
          <velocity>0 0 0 0 -0 0</velocity>
          <acceleration>0 0 0 0 -0 0</acceleration>
          <wrench>0 0 0 0 -0 0</wrench>
        </link>
      </model>
      <light name='sun'>
        <pose>0 0 10 0 -0 0</pose>
      </light>
    </state>
  </world>
</sdf>
